Traceback (most recent call last):
  File "C:\Users\FIKRI\AppData\Local\Programs\Python\Python311\Lib\site-packages\jupyter_core\utils\__init__.py", line 154, in wrapped
    asyncio.get_running_loop()
RuntimeError: no running event loop

During handling of the above exception, another exception occurred:

Traceback (most recent call last):
  File "C:\Users\FIKRI\AppData\Local\Programs\Python\Python311\Lib\site-packages\jupyter_cache\executors\utils.py", line 58, in single_nb_execution
    executenb(
  File "C:\Users\FIKRI\AppData\Local\Programs\Python\Python311\Lib\site-packages\nbclient\client.py", line 1319, in execute
    return NotebookClient(nb=nb, resources=resources, km=km, **kwargs).execute()
           ^^^^^^^^^^^^^^^^^^^^^^^^^^^^^^^^^^^^^^^^^^^^^^^^^^^^^^^^^^^^^^^^^^^^^
  File "C:\Users\FIKRI\AppData\Local\Programs\Python\Python311\Lib\site-packages\jupyter_core\utils\__init__.py", line 158, in wrapped
    return loop.run_until_complete(inner)
           ^^^^^^^^^^^^^^^^^^^^^^^^^^^^^^
  File "C:\Users\FIKRI\AppData\Local\Programs\Python\Python311\Lib\asyncio\base_events.py", line 653, in run_until_complete
    return future.result()
           ^^^^^^^^^^^^^^^
  File "C:\Users\FIKRI\AppData\Local\Programs\Python\Python311\Lib\site-packages\nbclient\client.py", line 709, in async_execute
    await self.async_execute_cell(
  File "C:\Users\FIKRI\AppData\Local\Programs\Python\Python311\Lib\site-packages\nbclient\client.py", line 1062, in async_execute_cell
    await self._check_raise_for_error(cell, cell_index, exec_reply)
  File "C:\Users\FIKRI\AppData\Local\Programs\Python\Python311\Lib\site-packages\nbclient\client.py", line 918, in _check_raise_for_error
    raise CellExecutionError.from_cell_and_msg(cell, exec_reply_content)
nbclient.exceptions.CellExecutionError: An error occurred while executing the following cell:
------------------
import pymysql
import pandas as pd

# Konfigurasi koneksi
host = "localhost"
user = "root"        # ganti sesuai user MySQL kamu
password = ""        # ganti sesuai password MySQL kamu
database = "psd"

# Buat koneksi
connection = pymysql.connect(
    host=host,
    user=user,
    password=password,
    database=database
)

try:
    # Baca data dari tabel iris_full
    query = "SELECT * FROM iris_full"
    df = pd.read_sql(query, connection)

    # Tampilkan 5 data teratas
    print(df.head())

finally:
    connection.close()

------------------


[31m---------------------------------------------------------------------------[39m
[31mConnectionRefusedError[39m                    Traceback (most recent call last)
[36mFile [39m[32m~\AppData\Local\Programs\Python\Python311\Lib\site-packages\pymysql\connections.py:661[39m, in [36mConnection.connect[39m[34m(self, sock)[39m
[32m    660[39m [38;5;28;01mtry[39;00m:
[32m--> [39m[32m661[39m     sock = [43msocket[49m[43m.[49m[43mcreate_connection[49m[43m([49m
[32m    662[39m [43m        [49m[43m([49m[38;5;28;43mself[39;49m[43m.[49m[43mhost[49m[43m,[49m[43m [49m[38;5;28;43mself[39;49m[43m.[49m[43mport[49m[43m)[49m[43m,[49m[43m [49m[38;5;28;43mself[39;49m[43m.[49m[43mconnect_timeout[49m[43m,[49m[43m [49m[43m*[49m[43m*[49m[43mkwargs[49m
[32m    663[39m [43m    [49m[43m)[49m
[32m    664[39m     [38;5;28;01mbreak[39;00m

[36mFile [39m[32m~\AppData\Local\Programs\Python\Python311\Lib\socket.py:851[39m, in [36mcreate_connection[39m[34m(address, timeout, source_address, all_errors)[39m
[32m    850[39m [38;5;28;01mif[39;00m [38;5;129;01mnot[39;00m all_errors:
[32m--> [39m[32m851[39m     [38;5;28;01mraise[39;00m exceptions[[32m0[39m]
[32m    852[39m [38;5;28;01mraise[39;00m ExceptionGroup([33m"[39m[33mcreate_connection failed[39m[33m"[39m, exceptions)

[36mFile [39m[32m~\AppData\Local\Programs\Python\Python311\Lib\socket.py:836[39m, in [36mcreate_connection[39m[34m(address, timeout, source_address, all_errors)[39m
[32m    835[39m     sock.bind(source_address)
[32m--> [39m[32m836[39m [43msock[49m[43m.[49m[43mconnect[49m[43m([49m[43msa[49m[43m)[49m
[32m    837[39m [38;5;66;03m# Break explicitly a reference cycle[39;00m

[31mConnectionRefusedError[39m: [WinError 10061] No connection could be made because the target machine actively refused it

During handling of the above exception, another exception occurred:

[31mOperationalError[39m                          Traceback (most recent call last)
[36mCell[39m[36m [39m[32mIn[1][39m[32m, line 11[39m
[32m      8[39m database = [33m"[39m[33mpsd[39m[33m"[39m
[32m     10[39m [38;5;66;03m# Buat koneksi[39;00m
[32m---> [39m[32m11[39m connection = [43mpymysql[49m[43m.[49m[43mconnect[49m[43m([49m
[32m     12[39m [43m    [49m[43mhost[49m[43m=[49m[43mhost[49m[43m,[49m
[32m     13[39m [43m    [49m[43muser[49m[43m=[49m[43muser[49m[43m,[49m
[32m     14[39m [43m    [49m[43mpassword[49m[43m=[49m[43mpassword[49m[43m,[49m
[32m     15[39m [43m    [49m[43mdatabase[49m[43m=[49m[43mdatabase[49m
[32m     16[39m [43m)[49m
[32m     18[39m [38;5;28;01mtry[39;00m:
[32m     19[39m     [38;5;66;03m# Baca data dari tabel iris_full[39;00m
[32m     20[39m     query = [33m"[39m[33mSELECT * FROM iris_full[39m[33m"[39m

[36mFile [39m[32m~\AppData\Local\Programs\Python\Python311\Lib\site-packages\pymysql\connections.py:365[39m, in [36mConnection.__init__[39m[34m(self, user, password, host, database, unix_socket, port, charset, collation, sql_mode, read_default_file, conv, use_unicode, client_flag, cursorclass, init_command, connect_timeout, read_default_group, autocommit, local_infile, max_allowed_packet, defer_connect, auth_plugin_map, read_timeout, write_timeout, bind_address, binary_prefix, program_name, server_public_key, ssl, ssl_ca, ssl_cert, ssl_disabled, ssl_key, ssl_key_password, ssl_verify_cert, ssl_verify_identity, compress, named_pipe, passwd, db)[39m
[32m    363[39m     [38;5;28mself[39m._sock = [38;5;28;01mNone[39;00m
[32m    364[39m [38;5;28;01melse[39;00m:
[32m--> [39m[32m365[39m     [38;5;28;43mself[39;49m[43m.[49m[43mconnect[49m[43m([49m[43m)[49m

[36mFile [39m[32m~\AppData\Local\Programs\Python\Python311\Lib\site-packages\pymysql\connections.py:723[39m, in [36mConnection.connect[39m[34m(self, sock)[39m
[32m    721[39m     [38;5;28;01mif[39;00m DEBUG:
[32m    722[39m         [38;5;28mprint[39m(exc.traceback)
[32m--> [39m[32m723[39m     [38;5;28;01mraise[39;00m exc
[32m    725[39m [38;5;66;03m# If e is neither DatabaseError or IOError, It's a bug.[39;00m
[32m    726[39m [38;5;66;03m# But raising AssertionError hides original error.[39;00m
[32m    727[39m [38;5;66;03m# So just reraise it.[39;00m
[32m    728[39m [38;5;28;01mraise[39;00m

[31mOperationalError[39m: (2003, "Can't connect to MySQL server on 'localhost' ([WinError 10061] No connection could be made because the target machine actively refused it)")

